[ 2023-09-28 00:07:02,565 ] 224 werkzeug - INFO - [31m[1mWARNING: This is a development server. Do not use it in a production deployment. Use a production WSGI server instead.[0m
 * Running on all addresses (0.0.0.0)
 * Running on http://127.0.0.1:5000
 * Running on http://192.168.43.225:5000
[ 2023-09-28 00:07:02,565 ] 224 werkzeug - INFO - [33mPress CTRL+C to quit[0m
[ 2023-09-28 00:07:16,249 ] 224 werkzeug - INFO - 127.0.0.1 - - [28/Sep/2023 00:07:16] "GET / HTTP/1.1" 200 -
[ 2023-09-28 00:07:19,274 ] 224 werkzeug - INFO - 127.0.0.1 - - [28/Sep/2023 00:07:19] "GET /predict HTTP/1.1" 200 -
[ 2023-09-28 00:07:20,281 ] 45 root - INFO - Exception Occurred in prediction pipeline
[ 2023-09-28 00:07:20,282 ] 1741 application - ERROR - Exception on /predict [POST]
Traceback (most recent call last):
  File "C:\Users\hp\AppData\Local\Programs\Python\Python39\lib\site-packages\pandas\core\indexes\base.py", line 3621, in get_loc
    return self._engine.get_loc(casted_key)
  File "pandas\_libs\index.pyx", line 136, in pandas._libs.index.IndexEngine.get_loc
  File "pandas\_libs\index.pyx", line 142, in pandas._libs.index.IndexEngine.get_loc
TypeError: '(slice(None, None, None), slice(None, -2, None))' is an invalid key

During handling of the above exception, another exception occurred:

Traceback (most recent call last):
  File "E:\SIH Predictive model\src\pipeline\prediction_pipeline.py", line 40, in get_data_as_dataframe
    df=df[: , :-2]
  File "C:\Users\hp\AppData\Local\Programs\Python\Python39\lib\site-packages\pandas\core\frame.py", line 3505, in __getitem__
    indexer = self.columns.get_loc(key)
  File "C:\Users\hp\AppData\Local\Programs\Python\Python39\lib\site-packages\pandas\core\indexes\base.py", line 3628, in get_loc
    self._check_indexing_error(key)
  File "C:\Users\hp\AppData\Local\Programs\Python\Python39\lib\site-packages\pandas\core\indexes\base.py", line 5637, in _check_indexing_error
    raise InvalidIndexError(key)
pandas.errors.InvalidIndexError: (slice(None, None, None), slice(None, -2, None))

During handling of the above exception, another exception occurred:

Traceback (most recent call last):
  File "C:\Users\hp\AppData\Local\Programs\Python\Python39\lib\site-packages\flask\app.py", line 2525, in wsgi_app
    response = self.full_dispatch_request()
  File "C:\Users\hp\AppData\Local\Programs\Python\Python39\lib\site-packages\flask\app.py", line 1822, in full_dispatch_request
    rv = self.handle_user_exception(e)
  File "C:\Users\hp\AppData\Local\Programs\Python\Python39\lib\site-packages\flask\app.py", line 1820, in full_dispatch_request
    rv = self.dispatch_request()
  File "C:\Users\hp\AppData\Local\Programs\Python\Python39\lib\site-packages\flask\app.py", line 1796, in dispatch_request
    return self.ensure_sync(self.view_functions[rule.endpoint])(**view_args)
  File "E:\SIH Predictive model\application.py", line 28, in predict_datapoint
    final_new_data = data.get_data_as_dataframe()
  File "E:\SIH Predictive model\src\pipeline\prediction_pipeline.py", line 46, in get_data_as_dataframe
    raise CustomException(e, sys)
src.exception.CustomException: Error occured in python script name [E:\SIH Predictive model\src\pipeline\prediction_pipeline.py] line number [40] error message [(slice(None, None, None), slice(None, -2, None))]
[ 2023-09-28 00:07:20,430 ] 224 werkzeug - INFO - 127.0.0.1 - - [28/Sep/2023 00:07:20] "[35m[1mPOST /predict HTTP/1.1[0m" 500 -
[ 2023-09-28 00:10:50,227 ] 224 werkzeug - INFO - 127.0.0.1 - - [28/Sep/2023 00:10:50] "GET / HTTP/1.1" 200 -
[ 2023-09-28 00:10:51,879 ] 224 werkzeug - INFO - 127.0.0.1 - - [28/Sep/2023 00:10:51] "GET /predict HTTP/1.1" 200 -
[ 2023-09-28 00:10:52,691 ] 45 root - INFO - Exception Occurred in prediction pipeline
[ 2023-09-28 00:10:52,692 ] 1741 application - ERROR - Exception on /predict [POST]
Traceback (most recent call last):
  File "C:\Users\hp\AppData\Local\Programs\Python\Python39\lib\site-packages\pandas\core\indexes\base.py", line 3621, in get_loc
    return self._engine.get_loc(casted_key)
  File "pandas\_libs\index.pyx", line 136, in pandas._libs.index.IndexEngine.get_loc
  File "pandas\_libs\index.pyx", line 142, in pandas._libs.index.IndexEngine.get_loc
TypeError: '(slice(None, None, None), slice(None, -2, None))' is an invalid key

During handling of the above exception, another exception occurred:

Traceback (most recent call last):
  File "E:\SIH Predictive model\src\pipeline\prediction_pipeline.py", line 40, in get_data_as_dataframe
    df=df.iloc[: , :-2]
  File "C:\Users\hp\AppData\Local\Programs\Python\Python39\lib\site-packages\pandas\core\frame.py", line 3505, in __getitem__
    indexer = self.columns.get_loc(key)
  File "C:\Users\hp\AppData\Local\Programs\Python\Python39\lib\site-packages\pandas\core\indexes\base.py", line 3628, in get_loc
    self._check_indexing_error(key)
  File "C:\Users\hp\AppData\Local\Programs\Python\Python39\lib\site-packages\pandas\core\indexes\base.py", line 5637, in _check_indexing_error
    raise InvalidIndexError(key)
pandas.errors.InvalidIndexError: (slice(None, None, None), slice(None, -2, None))

During handling of the above exception, another exception occurred:

Traceback (most recent call last):
  File "C:\Users\hp\AppData\Local\Programs\Python\Python39\lib\site-packages\flask\app.py", line 2525, in wsgi_app
    response = self.full_dispatch_request()
  File "C:\Users\hp\AppData\Local\Programs\Python\Python39\lib\site-packages\flask\app.py", line 1822, in full_dispatch_request
    rv = self.handle_user_exception(e)
  File "C:\Users\hp\AppData\Local\Programs\Python\Python39\lib\site-packages\flask\app.py", line 1820, in full_dispatch_request
    rv = self.dispatch_request()
  File "C:\Users\hp\AppData\Local\Programs\Python\Python39\lib\site-packages\flask\app.py", line 1796, in dispatch_request
    return self.ensure_sync(self.view_functions[rule.endpoint])(**view_args)
  File "E:\SIH Predictive model\application.py", line 28, in predict_datapoint
    final_new_data = data.get_data_as_dataframe()
  File "E:\SIH Predictive model\src\pipeline\prediction_pipeline.py", line 46, in get_data_as_dataframe
    raise CustomException(e, sys)
src.exception.CustomException: Error occured in python script name [E:\SIH Predictive model\src\pipeline\prediction_pipeline.py] line number [40] error message [(slice(None, None, None), slice(None, -2, None))]
[ 2023-09-28 00:10:52,697 ] 224 werkzeug - INFO - 127.0.0.1 - - [28/Sep/2023 00:10:52] "[35m[1mPOST /predict HTTP/1.1[0m" 500 -
[ 2023-09-28 00:12:23,239 ] 224 werkzeug - INFO - 127.0.0.1 - - [28/Sep/2023 00:12:23] "GET / HTTP/1.1" 200 -
[ 2023-09-28 00:12:26,064 ] 224 werkzeug - INFO - 127.0.0.1 - - [28/Sep/2023 00:12:26] "GET /predict HTTP/1.1" 200 -
[ 2023-09-28 00:12:26,889 ] 45 root - INFO - Exception Occurred in prediction pipeline
[ 2023-09-28 00:12:26,890 ] 1741 application - ERROR - Exception on /predict [POST]
Traceback (most recent call last):
  File "C:\Users\hp\AppData\Local\Programs\Python\Python39\lib\site-packages\pandas\core\indexes\base.py", line 3621, in get_loc
    return self._engine.get_loc(casted_key)
  File "pandas\_libs\index.pyx", line 136, in pandas._libs.index.IndexEngine.get_loc
  File "pandas\_libs\index.pyx", line 142, in pandas._libs.index.IndexEngine.get_loc
TypeError: '(slice(None, None, None), slice(None, -2, None))' is an invalid key

During handling of the above exception, another exception occurred:

Traceback (most recent call last):
  File "E:\SIH Predictive model\src\pipeline\prediction_pipeline.py", line 40, in get_data_as_dataframe
    df=df.iloc[: , :-2]
  File "C:\Users\hp\AppData\Local\Programs\Python\Python39\lib\site-packages\pandas\core\frame.py", line 3505, in __getitem__
    indexer = self.columns.get_loc(key)
  File "C:\Users\hp\AppData\Local\Programs\Python\Python39\lib\site-packages\pandas\core\indexes\base.py", line 3628, in get_loc
    self._check_indexing_error(key)
  File "C:\Users\hp\AppData\Local\Programs\Python\Python39\lib\site-packages\pandas\core\indexes\base.py", line 5637, in _check_indexing_error
    raise InvalidIndexError(key)
pandas.errors.InvalidIndexError: (slice(None, None, None), slice(None, -2, None))

During handling of the above exception, another exception occurred:

Traceback (most recent call last):
  File "C:\Users\hp\AppData\Local\Programs\Python\Python39\lib\site-packages\flask\app.py", line 2525, in wsgi_app
    response = self.full_dispatch_request()
  File "C:\Users\hp\AppData\Local\Programs\Python\Python39\lib\site-packages\flask\app.py", line 1822, in full_dispatch_request
    rv = self.handle_user_exception(e)
  File "C:\Users\hp\AppData\Local\Programs\Python\Python39\lib\site-packages\flask\app.py", line 1820, in full_dispatch_request
    rv = self.dispatch_request()
  File "C:\Users\hp\AppData\Local\Programs\Python\Python39\lib\site-packages\flask\app.py", line 1796, in dispatch_request
    return self.ensure_sync(self.view_functions[rule.endpoint])(**view_args)
  File "E:\SIH Predictive model\application.py", line 28, in predict_datapoint
    final_new_data = data.get_data_as_dataframe()
  File "E:\SIH Predictive model\src\pipeline\prediction_pipeline.py", line 46, in get_data_as_dataframe
    raise CustomException(e, sys)
src.exception.CustomException: Error occured in python script name [E:\SIH Predictive model\src\pipeline\prediction_pipeline.py] line number [40] error message [(slice(None, None, None), slice(None, -2, None))]
[ 2023-09-28 00:12:26,893 ] 224 werkzeug - INFO - 127.0.0.1 - - [28/Sep/2023 00:12:26] "[35m[1mPOST /predict HTTP/1.1[0m" 500 -
