[ 2023-09-28 00:13:49,455 ] 224 werkzeug - INFO - [31m[1mWARNING: This is a development server. Do not use it in a production deployment. Use a production WSGI server instead.[0m
 * Running on all addresses (0.0.0.0)
 * Running on http://127.0.0.1:5000
 * Running on http://192.168.43.225:5000
[ 2023-09-28 00:13:49,455 ] 224 werkzeug - INFO - [33mPress CTRL+C to quit[0m
[ 2023-09-28 00:14:00,824 ] 224 werkzeug - INFO - 127.0.0.1 - - [28/Sep/2023 00:14:00] "GET / HTTP/1.1" 200 -
[ 2023-09-28 00:14:04,155 ] 224 werkzeug - INFO - 127.0.0.1 - - [28/Sep/2023 00:14:04] "GET /predict HTTP/1.1" 200 -
[ 2023-09-28 00:14:05,726 ] 41 root - INFO - Dataframe Gathered
[ 2023-09-28 00:14:06,029 ] 1741 application - ERROR - Exception on /predict [POST]
Traceback (most recent call last):
  File "E:\SIH Predictive model\src\utils.py", line 52, in load_object
    return pickle.load(file_obj)
  File "sklearn\tree\_tree.pyx", line 692, in sklearn.tree._tree.Tree.__setstate__
  File "sklearn\tree\_tree.pyx", line 1379, in sklearn.tree._tree._check_node_ndarray
ValueError: node array from the pickle has an incompatible dtype:
- expected: [('left_child', '<i8'), ('right_child', '<i8'), ('feature', '<i8'), ('threshold', '<f8'), ('impurity', '<f8'), ('n_node_samples', '<i8'), ('weighted_n_node_samples', '<f8')]
- got     : {'names': ['left_child', 'right_child', 'feature', 'threshold', 'impurity', 'n_node_samples', 'weighted_n_node_samples', 'missing_go_to_left'], 'formats': ['<i8', '<i8', '<i8', '<f8', '<f8', '<i8', '<f8', 'u1'], 'offsets': [0, 8, 16, 24, 32, 40, 48, 56], 'itemsize': 64}

During handling of the above exception, another exception occurred:

Traceback (most recent call last):
  File "C:\Users\hp\AppData\Local\Programs\Python\Python39\lib\site-packages\flask\app.py", line 2525, in wsgi_app
    response = self.full_dispatch_request()
  File "C:\Users\hp\AppData\Local\Programs\Python\Python39\lib\site-packages\flask\app.py", line 1822, in full_dispatch_request
    rv = self.handle_user_exception(e)
  File "C:\Users\hp\AppData\Local\Programs\Python\Python39\lib\site-packages\flask\app.py", line 1820, in full_dispatch_request
    rv = self.dispatch_request()
  File "C:\Users\hp\AppData\Local\Programs\Python\Python39\lib\site-packages\flask\app.py", line 1796, in dispatch_request
    return self.ensure_sync(self.view_functions[rule.endpoint])(**view_args)
  File "E:\SIH Predictive model\application.py", line 29, in predict_datapoint
    predict_pipeline = PredictPipeline()
  File "E:\SIH Predictive model\src\pipeline\prediction_pipeline.py", line 14, in __init__
    self.model = load_object(self.model_path)
  File "E:\SIH Predictive model\src\utils.py", line 55, in load_object
    raise CustomException(e, sys)
src.exception.CustomException: Error occured in python script name [E:\SIH Predictive model\src\utils.py] line number [52] error message [node array from the pickle has an incompatible dtype:
- expected: [('left_child', '<i8'), ('right_child', '<i8'), ('feature', '<i8'), ('threshold', '<f8'), ('impurity', '<f8'), ('n_node_samples', '<i8'), ('weighted_n_node_samples', '<f8')]
- got     : {'names': ['left_child', 'right_child', 'feature', 'threshold', 'impurity', 'n_node_samples', 'weighted_n_node_samples', 'missing_go_to_left'], 'formats': ['<i8', '<i8', '<i8', '<f8', '<f8', '<i8', '<f8', 'u1'], 'offsets': [0, 8, 16, 24, 32, 40, 48, 56], 'itemsize': 64}]
[ 2023-09-28 00:14:06,035 ] 224 werkzeug - INFO - 127.0.0.1 - - [28/Sep/2023 00:14:06] "[35m[1mPOST /predict HTTP/1.1[0m" 500 -
